{
 "cells": [
  {
   "cell_type": "code",
   "execution_count": null,
   "metadata": {
    "collapsed": true
   },
   "outputs": [],
   "source": [
    "import boto3"
   ]
  },
  {
   "cell_type": "code",
   "execution_count": null,
   "metadata": {},
   "outputs": [],
   "source": [
    "dynamodb = boto3.resource('dynamodb',region_name='us-east-2',aws_access_key_id='AKIAIGI4TJMRN7BX3TSA',\n",
    "    aws_secret_access_key='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',)"
   ]
  },
  {
   "cell_type": "code",
   "execution_count": null,
   "metadata": {},
   "outputs": [],
   "source": [
    "table = dynamodb.Table('Shopping')"
   ]
  },
  {
   "cell_type": "code",
   "execution_count": 1,
   "metadata": {},
   "outputs": [],
   "source": [
    "item = {\n",
    "        'UserId': '522345',\n",
    "        \"Purchases\": {\n",
    "            \"1\":{ \n",
    "                \"items\": [\n",
    "                    {\"123\": 540,}\n",
    "                    \"234\": 660,\n",
    "                    \"567\": 810\n",
    "                ],\n",
    "                \"pos\": \"aldi\",\n",
    "                \"timestamp\": 1234567\n",
    "            },\n",
    "            \"2\":{\n",
    "                \"items\": {\n",
    "                    \"456\": 860,\n",
    "                    \"678\": 930,\n",
    "                    \"999\": 120\n",
    "                }\n",
    "            }\n",
    "        },\n",
    "        \"UserInfo\": \"blabla\"\n",
    "    }"
   ]
  },
  {
   "cell_type": "code",
   "execution_count": 3,
   "metadata": {},
   "outputs": [
    {
     "name": "stderr",
     "output_type": "stream",
     "text": [
      "ERROR:root:Internal Python error in the inspect module.\n",
      "Below is the traceback from this internal error.\n",
      "\n"
     ]
    },
    {
     "name": "stdout",
     "output_type": "stream",
     "text": [
      "Traceback (most recent call last):\n",
      "  File \"/home/maximilian/untitled/lib/python3.5/site-packages/IPython/core/interactiveshell.py\", line 2910, in run_code\n",
      "    exec(code_obj, self.user_global_ns, self.user_ns)\n",
      "  File \"<ipython-input-3-ec982428053e>\", line 1, in <module>\n",
      "    table.put_item(\n",
      "NameError: name 'table' is not defined\n",
      "\n",
      "During handling of the above exception, another exception occurred:\n",
      "\n",
      "Traceback (most recent call last):\n",
      "  File \"/home/maximilian/untitled/lib/python3.5/site-packages/IPython/core/interactiveshell.py\", line 1828, in showtraceback\n",
      "    stb = value._render_traceback_()\n",
      "AttributeError: 'NameError' object has no attribute '_render_traceback_'\n",
      "\n",
      "During handling of the above exception, another exception occurred:\n",
      "\n",
      "Traceback (most recent call last):\n",
      "  File \"/home/maximilian/untitled/lib/python3.5/site-packages/IPython/core/ultratb.py\", line 1090, in get_records\n",
      "    return _fixed_getinnerframes(etb, number_of_lines_of_context, tb_offset)\n",
      "  File \"/home/maximilian/untitled/lib/python3.5/site-packages/IPython/core/ultratb.py\", line 311, in wrapped\n",
      "    return f(*args, **kwargs)\n",
      "  File \"/home/maximilian/untitled/lib/python3.5/site-packages/IPython/core/ultratb.py\", line 345, in _fixed_getinnerframes\n",
      "    records = fix_frame_records_filenames(inspect.getinnerframes(etb, context))\n",
      "  File \"/usr/lib/python3.5/inspect.py\", line 1453, in getinnerframes\n",
      "    frameinfo = (tb.tb_frame,) + getframeinfo(tb, context)\n",
      "  File \"/usr/lib/python3.5/inspect.py\", line 1410, in getframeinfo\n",
      "    filename = getsourcefile(frame) or getfile(frame)\n",
      "  File \"/usr/lib/python3.5/inspect.py\", line 672, in getsourcefile\n",
      "    if getattr(getmodule(object, filename), '__loader__', None) is not None:\n",
      "  File \"/usr/lib/python3.5/inspect.py\", line 701, in getmodule\n",
      "    file = getabsfile(object, _filename)\n",
      "  File \"/usr/lib/python3.5/inspect.py\", line 685, in getabsfile\n",
      "    return os.path.normcase(os.path.abspath(_filename))\n",
      "  File \"/home/maximilian/untitled/lib/python3.5/posixpath.py\", line 361, in abspath\n",
      "    cwd = os.getcwd()\n",
      "FileNotFoundError: [Errno 2] No such file or directory\n"
     ]
    },
    {
     "ename": "NameError",
     "evalue": "name 'table' is not defined",
     "traceback": [
      "\u001b[0;31m---------------------------------------------------------------------------\u001b[0m"
     ],
     "output_type": "error"
    }
   ],
   "source": [
    "table.put_item(\n",
    "   Item=item\n",
    "    )"
   ]
  },
  {
   "cell_type": "code",
   "execution_count": null,
   "metadata": {},
   "outputs": [],
   "source": [
    ""
   ]
  }
 ],
 "metadata": {
  "kernelspec": {
   "display_name": "Python 3",
   "language": "python",
   "name": "python3"
  },
  "language_info": {
   "codemirror_mode": {
    "name": "ipython",
    "version": 3.0
   },
   "file_extension": ".py",
   "mimetype": "text/x-python",
   "name": "python",
   "nbconvert_exporter": "python",
   "pygments_lexer": "ipython3",
   "version": "3.5.2"
  }
 },
 "nbformat": 4,
 "nbformat_minor": 0
}